Workbook

Sheet covariance
A1: Instruction: Type "=" in front of the formulas below to apply the calculation.
A2: Pay attention to the column and the row used in the formulas. For example, B6:B50 is the cell range including all the values of X.
A5: Observation | B5: ='more data'!A1 -> X | C5: Y | D5: Mean X | E5: Mean Y | F5: X - Mean(X) | G5: Y - Mean(Y) | H5: (X - Mean(X))*(Y - Mean(Y)) | J5: Results | K5: Notes
A6: 1 | B6: ='more data'!A9 -> 52.53 | C6: ='more data'!B9 -> 66.16 | D6: AVERAGE(B6:B50) | E6: AVERAGE(C6:C50) | F6: B6-D6 | G6: C6-E6 | H6: F6*G6 | I6: Sum (X - Mean(X))*(Y - Mean(Y)) | J6: SUM(H6:H50) | K6: Sum of covariation products
A7: 2 | B7: ='more data'!A11 -> 66.14 | C7: ='more data'!B11 -> 52.7 | I7: Sample Size N | J7: A50 | K7: Count of values in the dataset
A8: 3 | B8: ='more data'!A6 -> 49.94 | C8: ='more data'!B6 -> 59.7 | I8: Covariance | J8: J6/(J7-1) | K8: Sum of products over (N-1)
A9: 4 | B9: ='more data'!A41 -> 58.7 | C9: ='more data'!B41 -> 62.31
A10: 5 | B10: ='more data'!A16 -> 61.77 | C10: ='more data'!B16 -> 54.06 | I10: Standard Deviation SD(X) | J10: STDEV.S(B6:B50) | K10: Calculated using STDEV.S()
A11: 6 | B11: ='more data'!A32 -> 58.09 | C11: ='more data'!B32 -> 58.27 | I11: Standard Deviation SD(Y) | J11: STDEV.S(C6:C50) | K11: Calculated using STDEV.S()
A12: 7 | B12: ='more data'!A38 -> 56.57 | C12: ='more data'!B38 -> 57.44
A13: 8 | B13: ='more data'!A26 -> 62.34 | C13: ='more data'!B26 -> 56.53 | I13: Pearson's r (manual) | J13: J8/(J10*J11) | K13: Covariance over SD(X) times SD(Y)
A14: 9 | B14: ='more data'!A42 -> 68.77 | C14: ='more data'!B42 -> 56.86 | I14: Pearson's r (built-in) | J14: CORREL(B6:B50,C6:C50) | K14: Calculated using CORREL()
A15: 10 | B15: ='more data'!A30 -> 57.71 | C15: ='more data'!B30 -> 57.44
A16: 11 | B16: ='more data'!A25 -> 49.81 | C16: ='more data'!B25 -> 57
A17: 12 | B17: ='more data'!A3 -> 59.11 | C17: ='more data'!B3 -> 55.38
A18: 13 | B18: ='more data'!A18 -> 59.7 | C18: ='more data'!B18 -> 45.96
A19: 14 | B19: ='more data'!A23 -> 61.17 | C19: ='more data'!B23 -> 59.16
A20: 15 | B20: ='more data'!A28 -> 54.46 | C20: ='more data'!B28 -> 55.55
A21: 16 | B21: ='more data'!A19 -> 62.79 | C21: ='more data'!B19 -> 59.68
A22: 17 | B22: ='more data'!A7 -> 62.41 | C22: ='more data'!B7 -> 60.47
A23: 18 | B23: ='more data'!A10 -> 53.85 | C23: ='more data'!B10 -> 55.15
A24: 19 | B24: ='more data'!A24 -> 60.84 | C24: ='more data'!B24 -> 71.16
A25: 20 | B25: ='more data'!A5 -> 51.58 | C25: ='more data'!B5 -> 53.44
A26: 21 | B26: ='more data'!A8 -> 66.86 | C26: ='more data'!B8 -> 62.44
A27: 22 | B27: ='more data'!A31 -> 68.14 | C27: ='more data'!B31 -> 63.26
A28: 23 | B28: ='more data'!A22 -> 70.22 | C28: ='more data'!B22 -> 64.31
A29: 24 | B29: ='more data'!A12 -> 53.52 | C29: ='more data'!B12 -> 44.61
A30: 25 | B30: ='more data'!A13 -> 67.98 | C30: ='more data'!B13 -> 66.62
A31: 26 | B31: ='more data'!A37 -> 53.01 | C31: ='more data'!B37 -> 42.47
A32: 27 | B32: ='more data'!A33 -> 52.44 | C32: ='more data'!B33 -> 40.67
A33: 28 | B33: ='more data'!A39 -> 77.8 | C33: ='more data'!B39 -> 63.84
A34: 29 | B34: ='more data'!A2 -> 54.6 | C34: ='more data'!B2 -> 30.49
A35: 30 | B35: ='more data'!A4 -> 50.31 | C35: ='more data'!B4 -> 41.88
A36: 31 | B36: ='more data'!A21 -> 66.43 | C36: ='more data'!B21 -> 79.39
A37: 32 | B37: ='more data'!A36 -> 66.63 | C37: ='more data'!B36 -> 79.54
A38: 33 | B38: ='more data'!A27 -> 50.6 | C38: ='more data'!B27 -> 39.7
A39: 34 | B39: ='more data'!A14 -> 54.09 | C39: ='more data'!B14 -> 28.61
A40: 35 | B40: ='more data'!A20 -> 68.58 | C40: ='more data'!B20 -> 75.93
A41: 36 | B41: ='more data'!A15 -> 71.43 | C41: ='more data'!B15 -> 71.36
A42: 37 | B42: ='more data'!A44 -> 75.39 | C42: ='more data'!B44 -> 68.87
...

Sheet more data
A1: X | B1: Y_positive | C1: Y_negative | D1: Y_none | E1: Y_quad
A2: 54.6 | B2: 30.49 | C2: 53.24 | D2: 67.98 | E2: 85.39 | G2: Correlation | H2: Coefficient r
A3: 59.11 | B3: 55.38 | C3: 60.4 | D3: 60.34 | E3: 85.22 | G3: Y_positive to X | H3: =CORREL($B$2:$B$46,$A$2:$A$46) -> 0.74581736
A4: 50.31 | B4: 41.88 | C4: 41.95 | D4: 69.66 | E4: 86.59 | G4: Y_negative to X | H4: =CORREL($C$2:$C$46,$A$2:$A$46) -> -0.73255327
A5: 51.58 | B5: 53.44 | C5: 41.96 | D5: 57.92 | E5: 86.54 | G5: Y_none to X | H5: =CORREL($D$2:$D$46,$A$2:$A$46) -> -0.097975237
A6: 49.94 | B6: 59.7 | C6: 43.46 | D6: 69.3 | E6: 86.66 | G6: Y_quad to X | H6: =CORREL($E$2:$E$46,$A$2:$A$46) -> 0.54520613
A7: 62.41 | B7: 60.47 | C7: 32.41 | D7: 88.87 | E7: 86.31
A8: 66.86 | B8: 62.44 | C8: 15.75 | D8: 44.46 | E8: 88.21
A9: 52.53 | B9: 66.16 | C9: 46.31 | D9: 19.42 | E9: 85.69
A10: 53.85 | B10: 55.15 | C10: 53.53 | D10: 47.91 | E10: 85.03
A11: 66.14 | B11: 52.7 | C11: 26.46 | D11: 39.98 | E11: 86.24
A12: 53.52 | B12: 44.61 | C12: 53.6 | D12: 55.66 | E12: 86.25
A13: 67.98 | B13: 66.62 | C13: 52.88 | D13: 58.43 | E13: 89.52
A14: 54.09 | B14: 28.61 | C14: 63.12 | D14: 75.36 | E14: 86.25
A15: 71.43 | B15: 71.36 | C15: 40.07 | D15: 57.71 | E15: 91.11
A16: 61.77 | B16: 54.06 | C16: 46.84 | D16: 31.69 | E16: 86.72
A17: 39.8 | B17: 47.16 | C17: 65.18 | D17: 46.07 | E17: 93.44
A18: 59.7 | B18: 45.96 | C18: 54.16 | D18: 76.72 | E18: 85.78
... A46: 46.49 | B46: 41.83 | C46: 46.65 | D46: 67.82 | E46: 88.21
